<?xml version="1.0"?>
<robot name="bulldozer_bot"
  xmlns:xacro="http://www.ros.org/wiki/xacro">

  <material name="camera_grey">
    <color rgba="0.81 0.81 0.81 1.0" />
  </material>

  <material name="lidar_black">
    <color rgba="0.22 0.22 0.22 1.0" />
  </material>

  <link name="base_link">
    <visual>
      <geometry>
        <mesh filename="file:///$(find lunabot_simulation)/models/bulldozer_bot/bulldozer_bot_drivetrain.dae" />
      </geometry>
      <origin xyz="0 0 0.1625" rpy="0 0 1.5708" />
    </visual>
    <collision>
      <geometry>
        <mesh filename="file:///$(find lunabot_simulation)/models/bulldozer_bot/bulldozer_bot_drivetrain.stl" />
      </geometry>
      <origin xyz="0 0 0.1625" rpy="0 0 1.5708" />
    </collision>
    <inertial>
      <mass value="25.0" />
      <origin xyz="0 0 0.1625" />
      <inertia ixx="1.3669" ixy="0.0" ixz="0.0" iyy="3.3602" iyz="0.0" izz="4.7271" />
    </inertial>
  </link>

  <link name="blade_link">
    <visual>
      <geometry>
        <mesh filename="file:///$(find lunabot_simulation)/models/bulldozer_bot/bulldozer_bot_blade.dae" />
      </geometry>
      <origin xyz="0 0 0" rpy="1.5708 0 1.5708" />
    </visual>
    <collision>
      <geometry>
        <mesh filename="file:///$(find lunabot_simulation)/models/bulldozer_bot/bulldozer_bot_blade.stl" />
      </geometry>
      <origin xyz="0 0 0" rpy="1.5708 0 1.5708" />
    </collision>
    <inertial>
      <mass value="5.0" />
      <origin xyz="0 0 0" />
      <inertia ixx="0.0833" ixy="0.0" ixz="0.0" iyy="0.1667" iyz="0.0" izz="0.2333" />
    </inertial>
  </link>

  <link name="blade_arm_link">
    <visual>
      <geometry>
        <mesh filename="file:///$(find lunabot_simulation)/models/bulldozer_bot/bulldozer_bot_blade_arm.dae" />
      </geometry>
      <origin xyz="0.127 0 0" rpy="-1.5708 0 1.5708" />
    </visual>
    <collision>
      <geometry>
        <mesh filename="file:///$(find lunabot_simulation)/models/bulldozer_bot/bulldozer_bot_blade_arm.stl" />
      </geometry>
      <origin xyz="0.127 0 0" rpy="-1.5708 0 1.5708" />
    </collision>
    <inertial>
      <mass value="5.0" />
      <origin xyz="0 0 0" />
      <inertia ixx="0.0833" ixy="0.0" ixz="0.0" iyy="0.1667" iyz="0.0" izz="0.2333" />
    </inertial>
  </link>

  <link name="d455_link">
    <visual>
      <geometry>
        <mesh filename="file:///$(find lunabot_simulation)/models/d455_camera/d455_camera.stl" />
      </geometry>
      <origin xyz="0 0.015 0" rpy="0 0 0" />
      <material name="camera_grey" />
    </visual>
    <collision>
      <geometry>
        <mesh filename="file:///$(find lunabot_simulation)/models/d455_camera/d455_camera.stl" />
      </geometry>
      <origin xyz="0 0.015 0" rpy="0 0 0" />
    </collision>
  </link>

  <link name="d456_link">
    <visual>
      <geometry>
        <mesh filename="file:///$(find lunabot_simulation)/models/d456_camera/d456_camera.stl" />
      </geometry>
      <origin xyz="0 -0.015 0" rpy="0 0 0" />
      <material name="camera_grey" />
    </visual>
    <collision>
      <geometry>
        <mesh filename="file:///$(find lunabot_simulation)/models/d456_camera/d456_camera.stl" />
      </geometry>
      <origin xyz="0 -0.015 0" rpy="0 0 0" />
    </collision>
  </link>

  <link name="s3_lidar_link">
    <visual>
      <geometry>
        <mesh filename="file:///$(find lunabot_simulation)/models/s3_lidar/s3_lidar.stl" />
      </geometry>
      <origin xyz="0 -0.0155 0" rpy="0 0 -1.5708" />
      <material name="lidar_black" />
    </visual>
    <collision>
      <geometry>
        <mesh filename="file:///$(find lunabot_simulation)/models/s3_lidar/s3_lidar.stl" />
      </geometry>
      <origin xyz="0 -0.0155 0" rpy="0 0 -1.5708" />
    </collision>
  </link>

  <link name="s2l_lidar_link">
    <visual>
      <geometry>
        <mesh filename="file:///$(find lunabot_simulation)/models/s2l_lidar/s2l_lidar.stl" />
      </geometry>
      <origin xyz="0 -0.015 0" rpy="0 3.14 -1.5708" />
      <material name="lidar_black" />
    </visual>
    <collision>
      <geometry>
        <mesh filename="file:///$(find lunabot_simulation)/models/s2l_lidar/s2l_lidar.stl" />
      </geometry>
      <origin xyz="0 -0.015 0" rpy="0 0 -1.5708" />
    </collision>
  </link>

  <link name="front_right_wheel_link">
    <inertial>
      <mass value="2.27" />
      <origin xyz="0 0 0" />
      <inertia ixx="0.0255" ixy="0.0" ixz="0.0" iyy="0.0255" iyz="0.0" izz="0.0510" />
    </inertial>
    <collision>
      <geometry>
        <cylinder length="0.127" radius="0.1016" />
      </geometry>
      <origin xyz="0 0 0" rpy="1.5708 0 0" />
    </collision>
  </link>

  <link name="front_left_wheel_link">
    <inertial>
      <mass value="2.27" />
      <origin xyz="0 0 0" />
      <inertia ixx="0.0255" ixy="0.0" ixz="0.0" iyy="0.0255" iyz="0.0" izz="0.0510" />
    </inertial>
    <collision>
      <geometry>
        <cylinder length="0.127" radius="0.1016" />
      </geometry>
      <origin xyz="0 0 0" rpy="-1.5708 0 0" />
    </collision>
  </link>

  <link name="rear_right_wheel_link">
    <inertial>
      <mass value="2.27" />
      <origin xyz="0 0 0" />
      <inertia ixx="0.0255" ixy="0.0" ixz="0.0" iyy="0.0255" iyz="0.0" izz="0.0510" />
    </inertial>
    <collision>
      <geometry>
        <cylinder length="0.127" radius="0.1016" />
      </geometry>
      <origin xyz="0 0 0" rpy="1.5708 0 0" />
    </collision>
  </link>

  <link name="rear_left_wheel_link">
    <inertial>
      <mass value="2.27" />
      <origin xyz="0 0 0" />
      <inertia ixx="0.0255" ixy="0.0" ixz="0.0" iyy="0.0255" iyz="0.0" izz="0.0510" />
    </inertial>
    <collision>
      <geometry>
        <cylinder length="0.127" radius="0.1016" />
      </geometry>
      <origin xyz="0 0 0" rpy="-1.5708 0 0" />
    </collision>
  </link>

  <joint name="base_rear_right_wheel_joint" type="continuous">
    <parent link="base_link" />
    <child link="rear_right_wheel_link" />
    <origin xyz="-0.235 -0.25 0.08" rpy="0 0 0" />
    <axis xyz="0 1 0" />
  </joint>

  <joint name="base_rear_left_wheel_joint" type="continuous">
    <parent link="base_link" />
    <child link="rear_left_wheel_link" />
    <origin xyz="-0.235 0.25 0.08" rpy="0 0 0" />
    <axis xyz="0 1 0" />
  </joint>

  <joint name="base_front_right_wheel_joint" type="continuous">
    <parent link="base_link" />
    <child link="front_right_wheel_link" />
    <origin xyz="0.215 -0.25 0.08" rpy="0 0 0" />
    <axis xyz="0 1 0" />
  </joint>

  <joint name="base_front_left_wheel_joint" type="continuous">
    <parent link="base_link" />
    <child link="front_left_wheel_link" />
    <origin xyz="0.215 0.25 0.08" rpy="0 0 0" />
    <axis xyz="0 1 0" />
  </joint>

  <joint name="base_blade_arm_joint" type="revolute">
    <parent link="base_link" />
    <child link="blade_arm_link" />
    <origin xyz="-0.1553 -0.0165 0.2424" rpy="0 0 3.14" />
    <axis xyz="0 1 0" />
    <limit effort="100" velocity="1.0" lower="-0.75" upper="0.75" />
    <dynamics damping="0.0" friction="0.0" />
  </joint>

  <joint name="blade_arm_joint" type="revolute">
    <parent link="blade_arm_link" />
    <child link="blade_link" />
    <origin xyz="0.22061 0.0 0.01284" rpy="0 0 3.14" />
    <axis xyz="0 1 0" />
    <limit effort="100" velocity="1.0" lower="-0.75" upper="0.75" />
    <dynamics damping="0.0" friction="0.0" />
  </joint>

  <joint name="base_d455_joint" type="fixed">
    <parent link="base_link" />
    <child link="d455_link" />
    <origin xyz="-0.125 0 0.5762" rpy="0 0 3.14" />
  </joint>

  <joint name="base_d456_joint" type="fixed">
    <parent link="base_link" />
    <child link="d456_link" />
    <origin xyz="-0.0555 0 0.5762" rpy="0 0.523599 0" />
  </joint>

  <joint name="base_s3_lidar_joint" type="fixed">
    <parent link="base_link" />
    <child link="s3_lidar_link" />
    <origin xyz="-0.09025 0 0.6" rpy="0 0 0" />
  </joint>

  <joint name="base_s2l_lidar_joint" type="fixed">
    <parent link="base_link" />
    <child link="s2l_lidar_link" />
    <origin xyz="0.26 0 0.175" rpy="0 0 0" />
  </joint>

</robot>